2020-07-10 20:06:16,869 Using parameter request.POST to get username with key settings.AXES_USERNAME_FORM_FIELD
2020-07-10 20:06:16,892 AXES: Getting access attempts that are newer than 2020-07-10 19:06:16.869648
2020-07-10 20:06:16,933 login: Se hace petición por el método: POST
2020-07-10 20:06:16,935 Using parameter credentials to get username with key settings.AXES_USERNAME_FORM_FIELD
2020-07-10 20:06:16,936 AXES: Getting access attempts that are newer than 2020-07-10 19:06:16.869648
2020-07-10 20:06:17,421 login: Se termina de autenticar el usuario tony
2020-07-10 20:06:17,421 login: Se genera el token
2020-07-10 20:06:17,424 Starting new HTTPS connection (1): api.telegram.org:443
2020-07-10 20:06:17,865 Internal Server Error: /login/
Traceback (most recent call last):
  File "/usr/local/lib/python3.8/site-packages/urllib3/connectionpool.py", line 670, in urlopen
    httplib_response = self._make_request(
  File "/usr/local/lib/python3.8/site-packages/urllib3/connectionpool.py", line 381, in _make_request
    self._validate_conn(conn)
  File "/usr/local/lib/python3.8/site-packages/urllib3/connectionpool.py", line 976, in _validate_conn
    conn.connect()
  File "/usr/local/lib/python3.8/site-packages/urllib3/connection.py", line 361, in connect
    self.sock = ssl_wrap_socket(
  File "/usr/local/lib/python3.8/site-packages/urllib3/util/ssl_.py", line 377, in ssl_wrap_socket
    return context.wrap_socket(sock, server_hostname=server_hostname)
  File "/usr/local/lib/python3.8/ssl.py", line 500, in wrap_socket
    return self.sslsocket_class._create(
  File "/usr/local/lib/python3.8/ssl.py", line 1040, in _create
    self.do_handshake()
  File "/usr/local/lib/python3.8/ssl.py", line 1309, in do_handshake
    self._sslobj.do_handshake()
ssl.SSLCertVerificationError: [SSL: CERTIFICATE_VERIFY_FAILED] certificate verify failed: self signed certificate in certificate chain (_ssl.c:1108)

During handling of the above exception, another exception occurred:

Traceback (most recent call last):
  File "/usr/local/lib/python3.8/site-packages/requests/adapters.py", line 439, in send
    resp = conn.urlopen(
  File "/usr/local/lib/python3.8/site-packages/urllib3/connectionpool.py", line 724, in urlopen
    retries = retries.increment(
  File "/usr/local/lib/python3.8/site-packages/urllib3/util/retry.py", line 439, in increment
    raise MaxRetryError(_pool, url, error or ResponseError(cause))
urllib3.exceptions.MaxRetryError: HTTPSConnectionPool(host='api.telegram.org', port=443): Max retries exceeded with url: /bot1223842209:AAFeSFdD7as7v8ziRJwmKpH95W0rr48o81w/sendMessage?chat_id=-1001441327218&parse_mode=Markdown&text=eibrsfprdbsc (Caused by SSLError(SSLCertVerificationError(1, '[SSL: CERTIFICATE_VERIFY_FAILED] certificate verify failed: self signed certificate in certificate chain (_ssl.c:1108)')))

During handling of the above exception, another exception occurred:

Traceback (most recent call last):
  File "/usr/local/lib/python3.8/site-packages/django/core/handlers/exception.py", line 34, in inner
    response = get_response(request)
  File "/usr/local/lib/python3.8/site-packages/django/core/handlers/base.py", line 115, in _get_response
    response = self.process_exception_by_middleware(e, request)
  File "/usr/local/lib/python3.8/site-packages/django/core/handlers/base.py", line 113, in _get_response
    response = wrapped_callback(request, *callback_args, **callback_kwargs)
  File "/usr/local/lib/python3.8/site-packages/axes/decorators.py", line 10, in inner
    return func(request, *args, **kwargs)
  File "/codigo/appWeb/decoradores.py", line 53, in interna
    return vista(request)
  File "/codigo/appWeb/views.py", line 44, in login
    api.enviar_token(token, user.chat_id)
  File "/codigo/appWeb/api.py", line 56, in enviar_token
    response = requests.get(send_text)
  File "/usr/local/lib/python3.8/site-packages/requests/api.py", line 76, in get
    return request('get', url, params=params, **kwargs)
  File "/usr/local/lib/python3.8/site-packages/requests/api.py", line 61, in request
    return session.request(method=method, url=url, **kwargs)
  File "/usr/local/lib/python3.8/site-packages/requests/sessions.py", line 530, in request
    resp = self.send(prep, **send_kwargs)
  File "/usr/local/lib/python3.8/site-packages/requests/sessions.py", line 643, in send
    r = adapter.send(request, **kwargs)
  File "/usr/local/lib/python3.8/site-packages/requests/adapters.py", line 514, in send
    raise SSLError(e, request=request)
requests.exceptions.SSLError: HTTPSConnectionPool(host='api.telegram.org', port=443): Max retries exceeded with url: /bot1223842209:AAFeSFdD7as7v8ziRJwmKpH95W0rr48o81w/sendMessage?chat_id=-1001441327218&parse_mode=Markdown&text=eibrsfprdbsc (Caused by SSLError(SSLCertVerificationError(1, '[SSL: CERTIFICATE_VERIFY_FAILED] certificate verify failed: self signed certificate in certificate chain (_ssl.c:1108)')))
2020-07-10 20:22:41,409 Using selector: EpollSelector
2020-07-10 20:23:11,199 Using parameter request.POST to get username with key settings.AXES_USERNAME_FORM_FIELD
2020-07-10 20:23:11,200 AXES: Getting access attempts that are newer than 2020-07-10 19:23:11.176965
2020-07-10 20:23:11,204 Using selector: EpollSelector
2020-07-10 20:23:11,218 login: Se hace petición por el método: GET
2020-07-10 20:23:16,254 Using parameter request.POST to get username with key settings.AXES_USERNAME_FORM_FIELD
2020-07-10 20:23:16,255 AXES: Getting access attempts that are newer than 2020-07-10 19:23:16.254814
2020-07-10 20:23:16,261 login: Se hace petición por el método: POST
2020-07-10 20:23:16,263 Using parameter credentials to get username with key settings.AXES_USERNAME_FORM_FIELD
2020-07-10 20:23:16,264 AXES: Getting access attempts that are newer than 2020-07-10 19:23:16.254814
2020-07-10 20:23:16,718 login: Se termina de autenticar el usuario tony
2020-07-10 20:23:16,718 login: Se genera el token
2020-07-10 20:23:16,768 Starting new HTTPS connection (1): api.telegram.org:443
2020-07-10 20:23:17,385 Internal Server Error: /login/
Traceback (most recent call last):
  File "/usr/local/lib/python3.8/site-packages/urllib3/connectionpool.py", line 670, in urlopen
    httplib_response = self._make_request(
  File "/usr/local/lib/python3.8/site-packages/urllib3/connectionpool.py", line 381, in _make_request
    self._validate_conn(conn)
  File "/usr/local/lib/python3.8/site-packages/urllib3/connectionpool.py", line 976, in _validate_conn
    conn.connect()
  File "/usr/local/lib/python3.8/site-packages/urllib3/connection.py", line 361, in connect
    self.sock = ssl_wrap_socket(
  File "/usr/local/lib/python3.8/site-packages/urllib3/util/ssl_.py", line 377, in ssl_wrap_socket
    return context.wrap_socket(sock, server_hostname=server_hostname)
  File "/usr/local/lib/python3.8/ssl.py", line 500, in wrap_socket
    return self.sslsocket_class._create(
  File "/usr/local/lib/python3.8/ssl.py", line 1040, in _create
    self.do_handshake()
  File "/usr/local/lib/python3.8/ssl.py", line 1309, in do_handshake
    self._sslobj.do_handshake()
ssl.SSLCertVerificationError: [SSL: CERTIFICATE_VERIFY_FAILED] certificate verify failed: self signed certificate in certificate chain (_ssl.c:1108)

During handling of the above exception, another exception occurred:

Traceback (most recent call last):
  File "/usr/local/lib/python3.8/site-packages/requests/adapters.py", line 439, in send
    resp = conn.urlopen(
  File "/usr/local/lib/python3.8/site-packages/urllib3/connectionpool.py", line 724, in urlopen
    retries = retries.increment(
  File "/usr/local/lib/python3.8/site-packages/urllib3/util/retry.py", line 439, in increment
    raise MaxRetryError(_pool, url, error or ResponseError(cause))
urllib3.exceptions.MaxRetryError: HTTPSConnectionPool(host='api.telegram.org', port=443): Max retries exceeded with url: /bot1223842209:AAFeSFdD7as7v8ziRJwmKpH95W0rr48o81w/sendMessage?chat_id=-1001441327218&parse_mode=Markdown&text=amttrgldkdqp (Caused by SSLError(SSLCertVerificationError(1, '[SSL: CERTIFICATE_VERIFY_FAILED] certificate verify failed: self signed certificate in certificate chain (_ssl.c:1108)')))

During handling of the above exception, another exception occurred:

Traceback (most recent call last):
  File "/usr/local/lib/python3.8/site-packages/django/core/handlers/exception.py", line 34, in inner
    response = get_response(request)
  File "/usr/local/lib/python3.8/site-packages/django/core/handlers/base.py", line 115, in _get_response
    response = self.process_exception_by_middleware(e, request)
  File "/usr/local/lib/python3.8/site-packages/django/core/handlers/base.py", line 113, in _get_response
    response = wrapped_callback(request, *callback_args, **callback_kwargs)
  File "/usr/local/lib/python3.8/site-packages/axes/decorators.py", line 10, in inner
    return func(request, *args, **kwargs)
  File "/codigo/appWeb/decoradores.py", line 53, in interna
    return vista(request)
  File "/codigo/appWeb/views.py", line 44, in login
    api.enviar_token(token, user.chat_id)
  File "/codigo/appWeb/api.py", line 56, in enviar_token
    response = requests.get(send_text)
  File "/usr/local/lib/python3.8/site-packages/requests/api.py", line 76, in get
    return request('get', url, params=params, **kwargs)
  File "/usr/local/lib/python3.8/site-packages/requests/api.py", line 61, in request
    return session.request(method=method, url=url, **kwargs)
  File "/usr/local/lib/python3.8/site-packages/requests/sessions.py", line 530, in request
    resp = self.send(prep, **send_kwargs)
  File "/usr/local/lib/python3.8/site-packages/requests/sessions.py", line 643, in send
    r = adapter.send(request, **kwargs)
  File "/usr/local/lib/python3.8/site-packages/requests/adapters.py", line 514, in send
    raise SSLError(e, request=request)
requests.exceptions.SSLError: HTTPSConnectionPool(host='api.telegram.org', port=443): Max retries exceeded with url: /bot1223842209:AAFeSFdD7as7v8ziRJwmKpH95W0rr48o81w/sendMessage?chat_id=-1001441327218&parse_mode=Markdown&text=amttrgldkdqp (Caused by SSLError(SSLCertVerificationError(1, '[SSL: CERTIFICATE_VERIFY_FAILED] certificate verify failed: self signed certificate in certificate chain (_ssl.c:1108)')))
2020-07-10 20:23:17,953 Not Found: /favicon.ico
2020-07-10 20:25:32,986 Not Found: /esperando_token
2020-07-10 20:25:56,029 Using parameter request.POST to get username with key settings.AXES_USERNAME_FORM_FIELD
2020-07-10 20:25:56,030 AXES: Getting access attempts that are newer than 2020-07-10 19:25:56.029404
2020-07-10 20:25:56,037 login: Se hace petición por el método: GET
2020-07-10 20:26:03,836 Using parameter request.POST to get username with key settings.AXES_USERNAME_FORM_FIELD
2020-07-10 20:26:03,837 AXES: Getting access attempts that are newer than 2020-07-10 19:26:03.836763
2020-07-10 20:26:03,841 login: Se hace petición por el método: POST
2020-07-10 20:26:03,842 Using parameter credentials to get username with key settings.AXES_USERNAME_FORM_FIELD
2020-07-10 20:26:03,842 AXES: Getting access attempts that are newer than 2020-07-10 19:26:03.836763
2020-07-10 20:26:04,286 login: Se termina de autenticar el usuario tony
2020-07-10 20:26:04,286 login: Se genera el token
2020-07-10 20:26:04,289 Starting new HTTPS connection (1): api.telegram.org:443
2020-07-10 20:26:04,681 Internal Server Error: /login/
Traceback (most recent call last):
  File "/usr/local/lib/python3.8/site-packages/urllib3/connectionpool.py", line 670, in urlopen
    httplib_response = self._make_request(
  File "/usr/local/lib/python3.8/site-packages/urllib3/connectionpool.py", line 381, in _make_request
    self._validate_conn(conn)
  File "/usr/local/lib/python3.8/site-packages/urllib3/connectionpool.py", line 976, in _validate_conn
    conn.connect()
  File "/usr/local/lib/python3.8/site-packages/urllib3/connection.py", line 361, in connect
    self.sock = ssl_wrap_socket(
  File "/usr/local/lib/python3.8/site-packages/urllib3/util/ssl_.py", line 377, in ssl_wrap_socket
    return context.wrap_socket(sock, server_hostname=server_hostname)
  File "/usr/local/lib/python3.8/ssl.py", line 500, in wrap_socket
    return self.sslsocket_class._create(
  File "/usr/local/lib/python3.8/ssl.py", line 1040, in _create
    self.do_handshake()
  File "/usr/local/lib/python3.8/ssl.py", line 1309, in do_handshake
    self._sslobj.do_handshake()
ssl.SSLCertVerificationError: [SSL: CERTIFICATE_VERIFY_FAILED] certificate verify failed: self signed certificate in certificate chain (_ssl.c:1108)

During handling of the above exception, another exception occurred:

Traceback (most recent call last):
  File "/usr/local/lib/python3.8/site-packages/requests/adapters.py", line 439, in send
    resp = conn.urlopen(
  File "/usr/local/lib/python3.8/site-packages/urllib3/connectionpool.py", line 724, in urlopen
    retries = retries.increment(
  File "/usr/local/lib/python3.8/site-packages/urllib3/util/retry.py", line 439, in increment
    raise MaxRetryError(_pool, url, error or ResponseError(cause))
urllib3.exceptions.MaxRetryError: HTTPSConnectionPool(host='api.telegram.org', port=443): Max retries exceeded with url: /bot1223842209:AAFeSFdD7as7v8ziRJwmKpH95W0rr48o81w/sendMessage?chat_id=-1001441327218&parse_mode=Markdown&text=qytnjjotltkx (Caused by SSLError(SSLCertVerificationError(1, '[SSL: CERTIFICATE_VERIFY_FAILED] certificate verify failed: self signed certificate in certificate chain (_ssl.c:1108)')))

During handling of the above exception, another exception occurred:

Traceback (most recent call last):
  File "/usr/local/lib/python3.8/site-packages/django/core/handlers/exception.py", line 34, in inner
    response = get_response(request)
  File "/usr/local/lib/python3.8/site-packages/django/core/handlers/base.py", line 115, in _get_response
    response = self.process_exception_by_middleware(e, request)
  File "/usr/local/lib/python3.8/site-packages/django/core/handlers/base.py", line 113, in _get_response
    response = wrapped_callback(request, *callback_args, **callback_kwargs)
  File "/usr/local/lib/python3.8/site-packages/axes/decorators.py", line 10, in inner
    return func(request, *args, **kwargs)
  File "/codigo/appWeb/decoradores.py", line 53, in interna
    return vista(request)
  File "/codigo/appWeb/views.py", line 44, in login
    api.enviar_token(token, user.chat_id)
  File "/codigo/appWeb/api.py", line 56, in enviar_token
    response = requests.get(send_text)
  File "/usr/local/lib/python3.8/site-packages/requests/api.py", line 76, in get
    return request('get', url, params=params, **kwargs)
  File "/usr/local/lib/python3.8/site-packages/requests/api.py", line 61, in request
    return session.request(method=method, url=url, **kwargs)
  File "/usr/local/lib/python3.8/site-packages/requests/sessions.py", line 530, in request
    resp = self.send(prep, **send_kwargs)
  File "/usr/local/lib/python3.8/site-packages/requests/sessions.py", line 643, in send
    r = adapter.send(request, **kwargs)
  File "/usr/local/lib/python3.8/site-packages/requests/adapters.py", line 514, in send
    raise SSLError(e, request=request)
requests.exceptions.SSLError: HTTPSConnectionPool(host='api.telegram.org', port=443): Max retries exceeded with url: /bot1223842209:AAFeSFdD7as7v8ziRJwmKpH95W0rr48o81w/sendMessage?chat_id=-1001441327218&parse_mode=Markdown&text=qytnjjotltkx (Caused by SSLError(SSLCertVerificationError(1, '[SSL: CERTIFICATE_VERIFY_FAILED] certificate verify failed: self signed certificate in certificate chain (_ssl.c:1108)')))
2020-07-10 20:26:06,669 Using parameter request.POST to get username with key settings.AXES_USERNAME_FORM_FIELD
2020-07-10 20:26:06,670 AXES: Getting access attempts that are newer than 2020-07-10 19:26:06.669477
2020-07-10 20:26:06,674 login: Se hace petición por el método: GET
2020-07-10 20:28:16,324 Using selector: EpollSelector
2020-07-10 20:28:25,770 Using parameter request.POST to get username with key settings.AXES_USERNAME_FORM_FIELD
2020-07-10 20:28:25,771 AXES: Getting access attempts that are newer than 2020-07-10 19:28:25.768520
2020-07-10 20:28:25,776 Using selector: EpollSelector
2020-07-10 20:28:25,787 login: Se hace petición por el método: GET
2020-07-10 20:28:30,433 Using parameter request.POST to get username with key settings.AXES_USERNAME_FORM_FIELD
2020-07-10 20:28:30,434 AXES: Getting access attempts that are newer than 2020-07-10 19:28:30.433872
2020-07-10 20:28:30,440 login: Se hace petición por el método: POST
2020-07-10 20:28:30,441 Using parameter credentials to get username with key settings.AXES_USERNAME_FORM_FIELD
2020-07-10 20:28:30,442 AXES: Getting access attempts that are newer than 2020-07-10 19:28:30.433872
2020-07-10 20:28:30,977 login: Se termina de autenticar el usuario tony
2020-07-10 20:28:30,977 login: Se genera el token
2020-07-10 20:28:30,984 Starting new HTTPS connection (1): api.telegram.org:443
2020-07-10 20:28:31,789 https://api.telegram.org:443 "GET /bot1223842209:AAFeSFdD7as7v8ziRJwmKpH95W0rr48o81w/sendMessage?chat_id=-1001441327218&parse_mode=Markdown&text=cvlusevcyvys HTTP/1.1" 200 262
2020-07-10 20:28:31,794 login: Se envia el token: cvlusevcyvys
2020-07-10 20:28:31,896 login: Se guarda el token en el usuario
2020-07-10 20:28:31,982 solicitar_token: Se hace petición por el método: GET
2020-07-10 20:30:15,654 Using selector: EpollSelector
2020-07-10 20:30:33,261 Using parameter request.POST to get username with key settings.AXES_USERNAME_FORM_FIELD
2020-07-10 20:30:33,264 AXES: Getting access attempts that are newer than 2020-07-10 19:30:33.257363
2020-07-10 20:30:33,271 Using selector: EpollSelector
2020-07-10 20:30:33,287 login: Se hace petición por el método: GET
2020-07-10 20:30:37,742 Using parameter request.POST to get username with key settings.AXES_USERNAME_FORM_FIELD
2020-07-10 20:30:37,743 AXES: Getting access attempts that are newer than 2020-07-10 19:30:37.742848
2020-07-10 20:30:37,747 login: Se hace petición por el método: POST
2020-07-10 20:30:37,749 Using parameter credentials to get username with key settings.AXES_USERNAME_FORM_FIELD
2020-07-10 20:30:37,750 AXES: Getting access attempts that are newer than 2020-07-10 19:30:37.742848
2020-07-10 20:30:38,185 login: Se termina de autenticar el usuario tony
2020-07-10 20:30:38,185 login: Se genera el token
2020-07-10 20:30:38,191 Starting new HTTPS connection (1): api.telegram.org:443
2020-07-10 20:30:38,725 Internal Server Error: /login/
Traceback (most recent call last):
  File "/usr/local/lib/python3.8/site-packages/urllib3/connectionpool.py", line 670, in urlopen
    httplib_response = self._make_request(
  File "/usr/local/lib/python3.8/site-packages/urllib3/connectionpool.py", line 381, in _make_request
    self._validate_conn(conn)
  File "/usr/local/lib/python3.8/site-packages/urllib3/connectionpool.py", line 976, in _validate_conn
    conn.connect()
  File "/usr/local/lib/python3.8/site-packages/urllib3/connection.py", line 361, in connect
    self.sock = ssl_wrap_socket(
  File "/usr/local/lib/python3.8/site-packages/urllib3/util/ssl_.py", line 377, in ssl_wrap_socket
    return context.wrap_socket(sock, server_hostname=server_hostname)
  File "/usr/local/lib/python3.8/ssl.py", line 500, in wrap_socket
    return self.sslsocket_class._create(
  File "/usr/local/lib/python3.8/ssl.py", line 1040, in _create
    self.do_handshake()
  File "/usr/local/lib/python3.8/ssl.py", line 1309, in do_handshake
    self._sslobj.do_handshake()
ssl.SSLCertVerificationError: [SSL: CERTIFICATE_VERIFY_FAILED] certificate verify failed: self signed certificate in certificate chain (_ssl.c:1108)

During handling of the above exception, another exception occurred:

Traceback (most recent call last):
  File "/usr/local/lib/python3.8/site-packages/requests/adapters.py", line 439, in send
    resp = conn.urlopen(
  File "/usr/local/lib/python3.8/site-packages/urllib3/connectionpool.py", line 724, in urlopen
    retries = retries.increment(
  File "/usr/local/lib/python3.8/site-packages/urllib3/util/retry.py", line 439, in increment
    raise MaxRetryError(_pool, url, error or ResponseError(cause))
urllib3.exceptions.MaxRetryError: HTTPSConnectionPool(host='api.telegram.org', port=443): Max retries exceeded with url: /bot1223842209:AAFeSFdD7as7v8ziRJwmKpH95W0rr48o81w/sendMessage?chat_id=-1001441327218&parse_mode=Markdown&text=sqzvamwojtgw (Caused by SSLError(SSLCertVerificationError(1, '[SSL: CERTIFICATE_VERIFY_FAILED] certificate verify failed: self signed certificate in certificate chain (_ssl.c:1108)')))

During handling of the above exception, another exception occurred:

Traceback (most recent call last):
  File "/usr/local/lib/python3.8/site-packages/django/core/handlers/exception.py", line 34, in inner
    response = get_response(request)
  File "/usr/local/lib/python3.8/site-packages/django/core/handlers/base.py", line 115, in _get_response
    response = self.process_exception_by_middleware(e, request)
  File "/usr/local/lib/python3.8/site-packages/django/core/handlers/base.py", line 113, in _get_response
    response = wrapped_callback(request, *callback_args, **callback_kwargs)
  File "/usr/local/lib/python3.8/site-packages/axes/decorators.py", line 10, in inner
    return func(request, *args, **kwargs)
  File "/codigo/appWeb/decoradores.py", line 53, in interna
    return vista(request)
  File "/codigo/appWeb/views.py", line 44, in login
    api.enviar_token(token, user.chat_id)
  File "/codigo/appWeb/api.py", line 56, in enviar_token
    response = requests.get(send_text)
  File "/usr/local/lib/python3.8/site-packages/requests/api.py", line 76, in get
    return request('get', url, params=params, **kwargs)
  File "/usr/local/lib/python3.8/site-packages/requests/api.py", line 61, in request
    return session.request(method=method, url=url, **kwargs)
  File "/usr/local/lib/python3.8/site-packages/requests/sessions.py", line 530, in request
    resp = self.send(prep, **send_kwargs)
  File "/usr/local/lib/python3.8/site-packages/requests/sessions.py", line 643, in send
    r = adapter.send(request, **kwargs)
  File "/usr/local/lib/python3.8/site-packages/requests/adapters.py", line 514, in send
    raise SSLError(e, request=request)
requests.exceptions.SSLError: HTTPSConnectionPool(host='api.telegram.org', port=443): Max retries exceeded with url: /bot1223842209:AAFeSFdD7as7v8ziRJwmKpH95W0rr48o81w/sendMessage?chat_id=-1001441327218&parse_mode=Markdown&text=sqzvamwojtgw (Caused by SSLError(SSLCertVerificationError(1, '[SSL: CERTIFICATE_VERIFY_FAILED] certificate verify failed: self signed certificate in certificate chain (_ssl.c:1108)')))
2020-07-10 20:30:38,955 Not Found: /favicon.ico
2020-07-10 20:46:18,204 Using selector: EpollSelector
2020-07-10 20:46:32,398 Using parameter request.POST to get username with key settings.AXES_USERNAME_FORM_FIELD
2020-07-10 20:46:32,402 AXES: Getting access attempts that are newer than 2020-07-10 19:46:32.363171
2020-07-10 20:46:32,407 Using selector: EpollSelector
2020-07-10 20:46:32,452 login: Se hace petición por el método: GET
2020-07-10 20:46:38,752 Using parameter request.POST to get username with key settings.AXES_USERNAME_FORM_FIELD
2020-07-10 20:46:38,752 AXES: Getting access attempts that are newer than 2020-07-10 19:46:38.752280
2020-07-10 20:46:38,756 login: Se hace petición por el método: POST
2020-07-10 20:46:38,757 Using parameter credentials to get username with key settings.AXES_USERNAME_FORM_FIELD
2020-07-10 20:46:38,758 AXES: Getting access attempts that are newer than 2020-07-10 19:46:38.752280
2020-07-10 20:46:39,192 login: Se termina de autenticar el usuario tony
2020-07-10 20:46:39,192 login: Se genera el token
2020-07-10 20:46:39,252 Starting new HTTPS connection (1): api.telegram.org:443
2020-07-10 20:46:39,852 Internal Server Error: /login/
Traceback (most recent call last):
  File "/usr/local/lib/python3.8/site-packages/urllib3/connectionpool.py", line 670, in urlopen
    httplib_response = self._make_request(
  File "/usr/local/lib/python3.8/site-packages/urllib3/connectionpool.py", line 381, in _make_request
    self._validate_conn(conn)
  File "/usr/local/lib/python3.8/site-packages/urllib3/connectionpool.py", line 976, in _validate_conn
    conn.connect()
  File "/usr/local/lib/python3.8/site-packages/urllib3/connection.py", line 361, in connect
    self.sock = ssl_wrap_socket(
  File "/usr/local/lib/python3.8/site-packages/urllib3/util/ssl_.py", line 377, in ssl_wrap_socket
    return context.wrap_socket(sock, server_hostname=server_hostname)
  File "/usr/local/lib/python3.8/ssl.py", line 500, in wrap_socket
    return self.sslsocket_class._create(
  File "/usr/local/lib/python3.8/ssl.py", line 1040, in _create
    self.do_handshake()
  File "/usr/local/lib/python3.8/ssl.py", line 1309, in do_handshake
    self._sslobj.do_handshake()
ssl.SSLCertVerificationError: [SSL: CERTIFICATE_VERIFY_FAILED] certificate verify failed: self signed certificate in certificate chain (_ssl.c:1108)

During handling of the above exception, another exception occurred:

Traceback (most recent call last):
  File "/usr/local/lib/python3.8/site-packages/requests/adapters.py", line 439, in send
    resp = conn.urlopen(
  File "/usr/local/lib/python3.8/site-packages/urllib3/connectionpool.py", line 724, in urlopen
    retries = retries.increment(
  File "/usr/local/lib/python3.8/site-packages/urllib3/util/retry.py", line 439, in increment
    raise MaxRetryError(_pool, url, error or ResponseError(cause))
urllib3.exceptions.MaxRetryError: HTTPSConnectionPool(host='api.telegram.org', port=443): Max retries exceeded with url: /bot1223842209:AAFeSFdD7as7v8ziRJwmKpH95W0rr48o81w/sendMessage?chat_id=-1001441327218&parse_mode=Markdown&text=vybjylkuphqo (Caused by SSLError(SSLCertVerificationError(1, '[SSL: CERTIFICATE_VERIFY_FAILED] certificate verify failed: self signed certificate in certificate chain (_ssl.c:1108)')))

During handling of the above exception, another exception occurred:

Traceback (most recent call last):
  File "/usr/local/lib/python3.8/site-packages/django/core/handlers/exception.py", line 34, in inner
    response = get_response(request)
  File "/usr/local/lib/python3.8/site-packages/django/core/handlers/base.py", line 115, in _get_response
    response = self.process_exception_by_middleware(e, request)
  File "/usr/local/lib/python3.8/site-packages/django/core/handlers/base.py", line 113, in _get_response
    response = wrapped_callback(request, *callback_args, **callback_kwargs)
  File "/usr/local/lib/python3.8/site-packages/axes/decorators.py", line 10, in inner
    return func(request, *args, **kwargs)
  File "/codigo/appWeb/decoradores.py", line 53, in interna
    return vista(request)
  File "/codigo/appWeb/views.py", line 44, in login
    api.enviar_token(token, user.chat_id)
  File "/codigo/appWeb/api.py", line 56, in enviar_token
    response = requests.get(send_text)
  File "/usr/local/lib/python3.8/site-packages/requests/api.py", line 76, in get
    return request('get', url, params=params, **kwargs)
  File "/usr/local/lib/python3.8/site-packages/requests/api.py", line 61, in request
    return session.request(method=method, url=url, **kwargs)
  File "/usr/local/lib/python3.8/site-packages/requests/sessions.py", line 530, in request
    resp = self.send(prep, **send_kwargs)
  File "/usr/local/lib/python3.8/site-packages/requests/sessions.py", line 643, in send
    r = adapter.send(request, **kwargs)
  File "/usr/local/lib/python3.8/site-packages/requests/adapters.py", line 514, in send
    raise SSLError(e, request=request)
requests.exceptions.SSLError: HTTPSConnectionPool(host='api.telegram.org', port=443): Max retries exceeded with url: /bot1223842209:AAFeSFdD7as7v8ziRJwmKpH95W0rr48o81w/sendMessage?chat_id=-1001441327218&parse_mode=Markdown&text=vybjylkuphqo (Caused by SSLError(SSLCertVerificationError(1, '[SSL: CERTIFICATE_VERIFY_FAILED] certificate verify failed: self signed certificate in certificate chain (_ssl.c:1108)')))
2020-07-10 20:49:11,134 Using parameter request.POST to get username with key settings.AXES_USERNAME_FORM_FIELD
2020-07-10 20:49:11,134 AXES: Getting access attempts that are newer than 2020-07-10 19:49:11.134029
2020-07-10 20:49:11,140 login: Se hace petición por el método: GET
2020-07-10 20:49:15,594 Using parameter request.POST to get username with key settings.AXES_USERNAME_FORM_FIELD
2020-07-10 20:49:15,595 AXES: Getting access attempts that are newer than 2020-07-10 19:49:15.594267
2020-07-10 20:49:15,601 login: Se hace petición por el método: POST
2020-07-10 20:49:15,602 Using parameter credentials to get username with key settings.AXES_USERNAME_FORM_FIELD
2020-07-10 20:49:15,603 AXES: Getting access attempts that are newer than 2020-07-10 19:49:15.594267
2020-07-10 20:49:16,141 login: Se termina de autenticar el usuario tony
2020-07-10 20:49:16,142 login: Se genera el token
2020-07-10 20:49:16,144 Starting new HTTPS connection (1): api.telegram.org:443
2020-07-10 20:49:16,532 Internal Server Error: /login/
Traceback (most recent call last):
  File "/usr/local/lib/python3.8/site-packages/urllib3/connectionpool.py", line 670, in urlopen
    httplib_response = self._make_request(
  File "/usr/local/lib/python3.8/site-packages/urllib3/connectionpool.py", line 381, in _make_request
    self._validate_conn(conn)
  File "/usr/local/lib/python3.8/site-packages/urllib3/connectionpool.py", line 976, in _validate_conn
    conn.connect()
  File "/usr/local/lib/python3.8/site-packages/urllib3/connection.py", line 361, in connect
    self.sock = ssl_wrap_socket(
  File "/usr/local/lib/python3.8/site-packages/urllib3/util/ssl_.py", line 377, in ssl_wrap_socket
    return context.wrap_socket(sock, server_hostname=server_hostname)
  File "/usr/local/lib/python3.8/ssl.py", line 500, in wrap_socket
    return self.sslsocket_class._create(
  File "/usr/local/lib/python3.8/ssl.py", line 1040, in _create
    self.do_handshake()
  File "/usr/local/lib/python3.8/ssl.py", line 1309, in do_handshake
    self._sslobj.do_handshake()
ssl.SSLCertVerificationError: [SSL: CERTIFICATE_VERIFY_FAILED] certificate verify failed: self signed certificate in certificate chain (_ssl.c:1108)

During handling of the above exception, another exception occurred:

Traceback (most recent call last):
  File "/usr/local/lib/python3.8/site-packages/requests/adapters.py", line 439, in send
    resp = conn.urlopen(
  File "/usr/local/lib/python3.8/site-packages/urllib3/connectionpool.py", line 724, in urlopen
    retries = retries.increment(
  File "/usr/local/lib/python3.8/site-packages/urllib3/util/retry.py", line 439, in increment
    raise MaxRetryError(_pool, url, error or ResponseError(cause))
urllib3.exceptions.MaxRetryError: HTTPSConnectionPool(host='api.telegram.org', port=443): Max retries exceeded with url: /bot1223842209:AAFeSFdD7as7v8ziRJwmKpH95W0rr48o81w/sendMessage?chat_id=-1001441327218&parse_mode=Markdown&text=xbriuiblmhoy (Caused by SSLError(SSLCertVerificationError(1, '[SSL: CERTIFICATE_VERIFY_FAILED] certificate verify failed: self signed certificate in certificate chain (_ssl.c:1108)')))

During handling of the above exception, another exception occurred:

Traceback (most recent call last):
  File "/usr/local/lib/python3.8/site-packages/django/core/handlers/exception.py", line 34, in inner
    response = get_response(request)
  File "/usr/local/lib/python3.8/site-packages/django/core/handlers/base.py", line 115, in _get_response
    response = self.process_exception_by_middleware(e, request)
  File "/usr/local/lib/python3.8/site-packages/django/core/handlers/base.py", line 113, in _get_response
    response = wrapped_callback(request, *callback_args, **callback_kwargs)
  File "/usr/local/lib/python3.8/site-packages/axes/decorators.py", line 10, in inner
    return func(request, *args, **kwargs)
  File "/codigo/appWeb/decoradores.py", line 53, in interna
    return vista(request)
  File "/codigo/appWeb/views.py", line 44, in login
    api.enviar_token(token, user.chat_id)
  File "/codigo/appWeb/api.py", line 56, in enviar_token
    response = requests.get(send_text)
  File "/usr/local/lib/python3.8/site-packages/requests/api.py", line 76, in get
    return request('get', url, params=params, **kwargs)
  File "/usr/local/lib/python3.8/site-packages/requests/api.py", line 61, in request
    return session.request(method=method, url=url, **kwargs)
  File "/usr/local/lib/python3.8/site-packages/requests/sessions.py", line 530, in request
    resp = self.send(prep, **send_kwargs)
  File "/usr/local/lib/python3.8/site-packages/requests/sessions.py", line 643, in send
    r = adapter.send(request, **kwargs)
  File "/usr/local/lib/python3.8/site-packages/requests/adapters.py", line 514, in send
    raise SSLError(e, request=request)
requests.exceptions.SSLError: HTTPSConnectionPool(host='api.telegram.org', port=443): Max retries exceeded with url: /bot1223842209:AAFeSFdD7as7v8ziRJwmKpH95W0rr48o81w/sendMessage?chat_id=-1001441327218&parse_mode=Markdown&text=xbriuiblmhoy (Caused by SSLError(SSLCertVerificationError(1, '[SSL: CERTIFICATE_VERIFY_FAILED] certificate verify failed: self signed certificate in certificate chain (_ssl.c:1108)')))
2020-07-10 21:02:21,108 Using selector: EpollSelector
2020-07-10 21:02:28,605 Using parameter request.POST to get username with key settings.AXES_USERNAME_FORM_FIELD
2020-07-10 21:02:28,607 AXES: Getting access attempts that are newer than 2020-07-10 20:02:28.584252
2020-07-10 21:02:28,613 Using selector: EpollSelector
2020-07-10 21:02:28,640 login: Se hace petición por el método: GET
2020-07-10 21:02:33,942 Using parameter request.POST to get username with key settings.AXES_USERNAME_FORM_FIELD
2020-07-10 21:02:33,943 AXES: Getting access attempts that are newer than 2020-07-10 20:02:33.942404
2020-07-10 21:02:33,948 login: Se hace petición por el método: POST
2020-07-10 21:02:33,950 Using parameter credentials to get username with key settings.AXES_USERNAME_FORM_FIELD
2020-07-10 21:02:33,951 AXES: Getting access attempts that are newer than 2020-07-10 20:02:33.942404
2020-07-10 21:02:34,453 login: Se termina de autenticar el usuario tony
2020-07-10 21:02:34,454 login: Se genera el token
2020-07-10 21:02:34,504 Starting new HTTPS connection (1): api.telegram.org:443
2020-07-10 21:02:35,472 https://api.telegram.org:443 "GET /bot1223842209:AAFeSFdD7as7v8ziRJwmKpH95W0rr48o81w/sendMessage?chat_id=-1001441327218&parse_mode=Markdown&text=kwocqnqyoiax HTTP/1.1" 200 262
2020-07-10 21:02:35,482 login: Se envia el token: kwocqnqyoiax
2020-07-10 21:02:35,578 login: Se guarda el token en el usuario
2020-07-10 21:02:35,664 solicitar_token: Se hace petición por el método: GET
2020-07-10 21:02:59,688 solicitar_token: Se hace petición por el método: POST
2020-07-10 21:02:59,762 solicitar_token: Se limpia el token al usuario: tony
2020-07-10 21:02:59,865 servidores: Se intento una petición por el método: GET
2020-07-10 21:03:03,371 monitoreo: Se intento una petición por el método: GET
2020-07-10 21:03:03,435 Internal Server Error: /monitor/1/
Traceback (most recent call last):
  File "/usr/local/lib/python3.8/site-packages/django/core/handlers/exception.py", line 34, in inner
    response = get_response(request)
  File "/usr/local/lib/python3.8/site-packages/django/core/handlers/base.py", line 115, in _get_response
    response = self.process_exception_by_middleware(e, request)
  File "/usr/local/lib/python3.8/site-packages/django/core/handlers/base.py", line 113, in _get_response
    response = wrapped_callback(request, *callback_args, **callback_kwargs)
  File "/codigo/appWeb/views.py", line 124, in monitoreo
    env=environ['REQUESTS_CA_BUNDLE'] #Se respalda la variable de entorno REQUESTS_CA_BUNDLE
  File "/usr/local/lib/python3.8/os.py", line 675, in __getitem__
    raise KeyError(key) from None
KeyError: 'REQUESTS_CA_BUNDLE'
2020-07-10 21:05:25,287 Using selector: EpollSelector
2020-07-10 21:05:30,837 Using parameter request.POST to get username with key settings.AXES_USERNAME_FORM_FIELD
2020-07-10 21:05:30,839 AXES: Getting access attempts that are newer than 2020-07-10 20:05:30.835529
2020-07-10 21:05:30,843 Using selector: EpollSelector
2020-07-10 21:05:30,898 servidores: Se intento una petición por el método: GET
2020-07-10 21:05:34,257 monitoreo: Se intento una petición por el método: GET
2020-07-10 21:05:34,276 api.solicitar_datos_srv: url del servidor a monitorear: https://127.0.0.1:8000
2020-07-10 21:05:34,276 api.solicitar_datos_srv: Datos a consultar: {'username': 'tony', 'password': '+lULZP2BCU4ng9KQw9IECnENDj+H+FlJNMCQmk7QmmM=lsy4cqM='}
2020-07-10 21:05:34,282 Starting new HTTPS connection (1): 127.0.0.1:8000
2020-07-10 21:08:42,947 monitoreo: Se intento una petición por el método: GET
2020-07-10 21:08:42,983 Using selector: EpollSelector
2020-07-10 21:08:43,068 api.solicitar_datos_srv: url del servidor a monitorear: https://127.0.0.1:8000
2020-07-10 21:08:43,068 api.solicitar_datos_srv: Datos a consultar: {'username': 'tony', 'password': '+lULZP2BCU4ng9KQw9IECnENDj+H+FlJNMCQmk7QmmM=lsy4cqM='}
2020-07-10 21:08:43,074 Starting new HTTPS connection (1): 127.0.0.1:8000
2020-07-10 21:17:37,784 Using selector: EpollSelector
2020-07-10 21:17:47,956 monitoreo: Se intento una petición por el método: GET
2020-07-10 21:17:47,961 Using selector: EpollSelector
2020-07-10 21:17:48,075 Internal Server Error: /monitor/1/
Traceback (most recent call last):
  File "/codigo/appWeb/views.py", line 114, in monitoreo
    usuario = Usuario.objects.get(usr=nom_usuario)
  File "/usr/local/lib/python3.8/site-packages/django/db/models/manager.py", line 82, in manager_method
    return getattr(self.get_queryset(), name)(*args, **kwargs)
  File "/usr/local/lib/python3.8/site-packages/django/db/models/query.py", line 415, in get
    raise self.model.DoesNotExist(
appWeb.models.Usuario.DoesNotExist: Usuario matching query does not exist.

During handling of the above exception, another exception occurred:

Traceback (most recent call last):
  File "/usr/local/lib/python3.8/site-packages/django/core/handlers/exception.py", line 34, in inner
    response = get_response(request)
  File "/usr/local/lib/python3.8/site-packages/django/core/handlers/base.py", line 115, in _get_response
    response = self.process_exception_by_middleware(e, request)
  File "/usr/local/lib/python3.8/site-packages/django/core/handlers/base.py", line 113, in _get_response
    response = wrapped_callback(request, *callback_args, **callback_kwargs)
  File "/codigo/appWeb/views.py", line 116, in monitoreo
    logging.error('monitoreo: No se encontró el usuario: ' + nom_usuario)
TypeError: can only concatenate str (not "NoneType") to str
2020-07-10 21:17:50,698 Not Found: /monitor
2020-07-10 21:17:53,713 Using parameter request.POST to get username with key settings.AXES_USERNAME_FORM_FIELD
2020-07-10 21:17:53,720 AXES: Getting access attempts that are newer than 2020-07-10 20:17:53.660337
2020-07-10 21:17:53,728 login: Se hace petición por el método: GET
2020-07-10 21:17:59,128 Using parameter request.POST to get username with key settings.AXES_USERNAME_FORM_FIELD
2020-07-10 21:17:59,129 AXES: Getting access attempts that are newer than 2020-07-10 20:17:59.128059
2020-07-10 21:17:59,134 login: Se hace petición por el método: POST
2020-07-10 21:17:59,136 Using parameter credentials to get username with key settings.AXES_USERNAME_FORM_FIELD
2020-07-10 21:17:59,137 AXES: Getting access attempts that are newer than 2020-07-10 20:17:59.128059
2020-07-10 21:17:59,619 login: Se termina de autenticar el usuario tony
2020-07-10 21:17:59,620 login: Se genera el token
2020-07-10 21:17:59,624 Starting new HTTPS connection (1): api.telegram.org:443
2020-07-10 21:18:00,527 https://api.telegram.org:443 "GET /bot1223842209:AAFeSFdD7as7v8ziRJwmKpH95W0rr48o81w/sendMessage?chat_id=-1001441327218&parse_mode=Markdown&text=nrueckuhpsxp HTTP/1.1" 200 262
2020-07-10 21:18:00,533 login: Se envia el token: nrueckuhpsxp
2020-07-10 21:18:00,596 login: Se guarda el token en el usuario
2020-07-10 21:18:00,644 solicitar_token: Se hace petición por el método: GET
2020-07-10 21:18:20,968 solicitar_token: Se hace petición por el método: POST
2020-07-10 21:18:21,455 solicitar_token: Se limpia el token al usuario: tony
2020-07-10 21:18:21,656 servidores: Se intento una petición por el método: GET
2020-07-10 21:18:23,546 monitoreo: Se intento una petición por el método: GET
2020-07-10 21:18:23,555 monitoreo: Path cert: /tmp/srv_monitoreo_cert.crt
2020-07-10 21:18:23,555 api.solicitar_datos_srv: url del servidor a monitorear: https://127.0.0.1:8000
2020-07-10 21:18:23,555 api.solicitar_datos_srv: Datos a consultar: {'username': 'tony', 'password': '+lULZP2BCU4ng9KQw9IECnENDj+H+FlJNMCQmk7QmmM=lsy4cqM='}
2020-07-10 21:18:23,558 Starting new HTTPS connection (1): 127.0.0.1:8000
2020-07-10 21:21:52,216 Using selector: EpollSelector
2020-07-10 21:21:58,632 monitoreo: Se intento una petición por el método: GET
2020-07-10 21:21:58,638 Using selector: EpollSelector
2020-07-10 21:21:58,669 monitoreo: Path cert: /tmp/srv_monitoreo_cert.crt
2020-07-10 21:21:58,670 api.solicitar_datos_srv: url del servidor a monitorear: https://127.0.0.1:8000
2020-07-10 21:21:58,671 api.solicitar_datos_srv: Datos a consultar: {'username': 'tony', 'password': '+lULZP2BCU4ng9KQw9IECnENDj+H+FlJNMCQmk7QmmM=lsy4cqM='}
2020-07-10 21:21:58,678 Starting new HTTPS connection (1): 127.0.0.1:8000
2020-07-10 21:22:29,225 Using parameter request.POST to get username with key settings.AXES_USERNAME_FORM_FIELD
2020-07-10 21:22:29,226 AXES: Getting access attempts that are newer than 2020-07-10 20:22:29.223781
2020-07-10 21:22:29,231 Using selector: EpollSelector
2020-07-10 21:22:29,250 Using parameter request.POST to get username with key settings.AXES_USERNAME_FORM_FIELD
2020-07-10 21:22:29,250 AXES: Getting access attempts that are newer than 2020-07-10 20:22:29.249953
2020-07-10 21:22:41,460 Using parameter request.POST to get username with key settings.AXES_USERNAME_FORM_FIELD
2020-07-10 21:22:41,461 AXES: Getting access attempts that are newer than 2020-07-10 20:22:41.460161
2020-07-10 21:22:41,465 login: Se hace petición por el método: GET
2020-07-10 21:22:46,760 Using parameter request.POST to get username with key settings.AXES_USERNAME_FORM_FIELD
2020-07-10 21:22:46,761 AXES: Getting access attempts that are newer than 2020-07-10 20:22:46.760131
2020-07-10 21:22:46,769 login: Se hace petición por el método: POST
2020-07-10 21:22:46,771 Using parameter credentials to get username with key settings.AXES_USERNAME_FORM_FIELD
2020-07-10 21:22:46,772 AXES: Getting access attempts that are newer than 2020-07-10 20:22:46.760131
2020-07-10 21:22:47,257 login: Se termina de autenticar el usuario tony
2020-07-10 21:22:47,257 login: Se genera el token
2020-07-10 21:22:47,261 Starting new HTTPS connection (1): api.telegram.org:443
2020-07-10 21:22:48,006 https://api.telegram.org:443 "GET /bot1223842209:AAFeSFdD7as7v8ziRJwmKpH95W0rr48o81w/sendMessage?chat_id=-1001441327218&parse_mode=Markdown&text=lufhpdyvofuc HTTP/1.1" 200 262
2020-07-10 21:22:48,011 login: Se envia el token: lufhpdyvofuc
2020-07-10 21:22:48,077 login: Se guarda el token en el usuario
2020-07-10 21:22:48,160 solicitar_token: Se hace petición por el método: GET
2020-07-10 21:22:57,178 solicitar_token: Se hace petición por el método: POST
2020-07-10 21:22:57,227 solicitar_token: Se limpia el token al usuario: tony
2020-07-10 21:22:57,330 servidores: Se intento una petición por el método: GET
2020-07-10 21:22:58,885 monitoreo: Se intento una petición por el método: GET
2020-07-10 21:22:58,904 monitoreo: Path cert: /tmp/srv_monitoreo_cert.crt
2020-07-10 21:22:58,904 api.solicitar_datos_srv: url del servidor a monitorear: https://127.0.0.1:8000
2020-07-10 21:22:58,905 api.solicitar_datos_srv: Datos a consultar: {'username': 'tony', 'password': '+lULZP2BCU4ng9KQw9IECnENDj+H+FlJNMCQmk7QmmM=lsy4cqM='}
2020-07-10 21:22:58,912 Starting new HTTPS connection (1): 127.0.0.1:8000
2020-07-10 21:23:31,681 Not Found: /favicon.ico
